Workbook

Sheet Readme
A1: Scratchpad Dungeon · authoritative balance workbook
A2: Edit blue Value cells only. IDs, columns, sheets and protected metadata must stay intact.
A3: Import: npm run balance:import -- path/to/edited.xlsx
A4: Validate without writing: npm run balance:validate -- path/to/edited.xlsx
A5: Export fresh after an import: npm run balance:export
A6: The importer rejects formulas in input cells, unknown/missing/duplicate fields, invalid types, unsafe text and broken references.
A7: All sheets are validated together before any source or build is replaced.
A8: data/balance.json is the runtime source. This workbook is an editable export.
A9: Statistics recalculate in Excel/LibreOffice; import recomputes build data from input cells, never cached formula results.
A10: Reel statistics: level-one base face power and triple-match probability; excludes class powers, buffs, gear and target armour.
A11: Enemy HP statistics use the normal/boss/stronghold curve plus per-type multiplier. Other figures are baseline snapshots regenerated after import.
A12: Schema | B12: 1
A13: Schema digest | B13: b889ae28d1107419968dc059d0969609db38bb31509262f7e6a6fbb815743682
A14: Balance revision | B14: 1
A15: Source digest | B15: 6d2d6d6b8c46a364f6ff46f66d21672c4674b7105692c45eaccbeb8e2a59e7b3

Sheet Engine
A1: Stable field ID | B1: Entity ID | C1: Field / label | D1: Value (edit blue cells) | E1: Type | F1: Unit | G1: Minimum | H1: Maximum | I1: Notes
A2: /engine/mapWidth | B2: rule.engine | C2: mapWidth | D2: 11 | E2: number | G2: 0 | H2: 100000 | I2: READ ONLY
A3: /engine/mapHeight | B3: rule.engine | C3: mapHeight | D3: 9 | E3: number | G3: 0 | H3: 100000 | I3: READ ONLY
A4: /engine/maxSupportedParty | B4: rule.engine | C4: maxSupportedParty | D4: 3 | E4: number | G4: 0 | H4: 100000 | I4: READ ONLY
A5: /engine/reelsPerMachine | B5: rule.engine | C5: reelsPerMachine | D5: 3 | E5: number | G5: 0 | H5: 100000 | I5: READ ONLY
A6: /engine/criticalMatches | B6: rule.engine | C6: criticalMatches | D6: 3 | E6: number | G6: 0 | H6: 100000 | I6: READ ONLY

Sheet Progression
A1: Stable field ID | B1: Entity ID | C1: Field / label | D1: Value (edit blue cells) | E1: Type | F1: Unit | G1: Minimum | H1: Maximum | I1: Notes
A2: /rules/maxParty | B2: rule.rules | C2: maxParty | D2: 3 | E2: number | G2: 1 | H2: 3
A3: /rules/bagTypes | B3: rule.rules | C3: bagTypes | D3: 3 | E3: number | G3: 1 | H3: 3
A4: /rules/floors | B4: rule.rules | C4: floors | D4: 10 | E4: number | G4: 10 | H4: 10
A5: /rules/startingPoints | B5: rule.rules | C5: startingPoints | D5: 3 | E5: number | G5: 0 | H5: 100000
A6: /rules/levelHp | B6: rule.rules | C6: levelHp | D6: 6 | E6: number | G6: 1 | H6: 1000
A7: /rules/levelPoints | B7: rule.rules | C7: levelPoints | D7: 4 | E7: number | G7: 1 | H7: 1000
A8: /rules/xpPerLevel | B8: rule.rules | C8: xpPerLevel | D8: 12 | E8: number | G8: 1 | H8: 1000
A9: /rules/blankInscriptionCost | B9: rule.rules | C9: blankInscriptionCost | D9: 3 | E9: number | G9: 1 | H9: 1000
A10: /rules/stunArmourCost | B10: rule.rules | C10: stunArmourCost | D10: 6 | E10: number | G10: 1 | H10: 1000
A11: /rules/reviveHealthFraction | B11: rule.rules | C11: reviveHealthFraction | D11: 0.75 | E11: number | G11: 0.0001 | H11: 1
A12: /rules/fountainHealthFraction | B12: rule.rules | C12: fountainHealthFraction | D12: 0.3 | E12: number | G12: 0.0001 | H12: 1
A13: /rules/descentHeal | B13: rule.rules | C13: descentHeal | D13: 5 | E13: number | G13: 0 | H13: 100000
... A17: /rules/areaAttackTier | B17: rule.rules | C17: areaAttackTier | D17: 3 | E17: number | G17: 1 | H17: 4
A18: /tuning/victory.coefficient.1/value | B18: rule.tuning.victory.coefficient.1 | C18: victory · coefficient 1 | D18: 8 | E18: number | F18: count or coefficient | G18: 1 | H18: 100 | I18: Coefficient in: ( h, Math.round( (8 + state.depth * 2) * 0.85 *
A19: /tuning/victory.coefficient.1/category | B19: rule.tuning.victory.coefficient.1 | C19: victory · coefficient 1 | D19: Progression | E19: string | F19: count or coefficient | I19: READ ONLY
A20: /tuning/victory.coefficient.1/label | B20: rule.tuning.victory.coefficient.1 | C20: victory · coefficient 1 | D20: victory · coefficient 1 | E20: string | F20: count or coefficient | I20: READ ONLY
A21: /tuning/victory.coefficient.1/description | B21: rule.tuning.victory.coefficient.1 | C21: victory · coefficient 1 | D21: Coefficient in: ( h, Math.round( (8 + state.depth * 2) * 0.85 * | E21: string | F21: count or coefficient | I21: READ ONLY
A22: /tuning/victory.coefficient.1/unit | B22: rule.tuning.victory.coefficient.1 | C22: victory · coefficient 1 | D22: count or coefficient | E22: string | F22: count or coefficient | I22: READ ONLY
A23: /tuning/victory.coefficient.1/min | B23: rule.tuning.victory.coefficient.1 | C23: victory · coefficient 1 | D23: 0 | E23: number | F23: count or coefficient | G23: 1 | H23: 100 | I23: READ ONLY
A24: /tuning/victory.coefficient.1/max | B24: rule.tuning.victory.coefficient.1 | C24: victory · coefficient 1 | D24: 100 | E24: number | F24: count or coefficient | G24: 1 | H24: 100 | I24: READ ONLY
A25: /tuning/victory.coefficient.1/integer | B25: rule.tuning.victory.coefficient.1 | C25: victory · coefficient 1 | D25: TRUE | E25: boolean | F25: count or coefficient | I25: READ ONLY
A26: /tuning/victory.coefficient.2/value | B26: rule.tuning.victory.coefficient.2 | C26: victory · coefficient 2 | D26: 2 | E26: number | F26: count or coefficient | G26: 1 | H26: 100 | I26: Coefficient in: ath.round( (8 + state.depth * 2) * 0.85 * (state.
A27: /tuning/victory.coefficient.2/category | B27: rule.tuning.victory.coefficient.2 | C27: victory · coefficient 2 | D27: Progression | E27: string | F27: count or coefficient | I27: READ ONLY
A28: /tuning/victory.coefficient.2/label | B28: rule.tuning.victory.coefficient.2 | C28: victory · coefficient 2 | D28: victory · coefficient 2 | E28: string | F28: count or coefficient | I28: READ ONLY
A29: /tuning/victory.coefficient.2/description | B29: rule.tuning.victory.coefficient.2 | C29: victory · coefficient 2 | D29: Coefficient in: ath.round( (8 + state.depth * 2) * 0.85 * (state. | E29: string | F29: count or coefficient | I29: READ ONLY
A30: /tuning/victory.coefficient.2/unit | B30: rule.tuning.victory.coefficient.2 | C30: victory · coefficient 2 | D30: count or coefficient | E30: string | F30: count or coefficient | I30: READ ONLY
A31: /tuning/victory.coefficient.2/min | B31: rule.tuning.victory.coefficient.2 | C31: victory · coefficient 2 | D31: 0 | E31: number | F31: count or coefficient | G31: 1 | H31: 100 | I31: READ ONLY
A32: /tuning/victory.coefficient.2/max | B32: rule.tuning.victory.coefficient.2 | C32: victory · coefficient 2 | D32: 100 | E32: number | F32: count or coefficient | G32: 1 | H32: 100 | I32: READ ONLY
A33: /tuning/victory.coefficient.2/integer | B33: rule.tuning.victory.coefficient.2 | C33: victory · coefficient 2 | D33: TRUE | E33: boolean | F33: count or coefficient | I33: READ ONLY
A34: /tuning/victory.coefficient.3/value | B34: rule.tuning.victory.coefficient.3 | C34: victory · coefficient 3 | D34: 0.85 | E34: number | F34: probability or multiplier | G34: 0 | H34: 1 | I34: Coefficient in: (8 + state.depth * 2) * 0.85 * (state.encounterReward?.c
A35: /tuning/victory.coefficient.3/category | B35: rule.tuning.victory.coefficient.3 | C35: victory · coefficient 3 | D35: Progression | E35: string | F35: probability or multiplier | I35: READ ONLY
A36: /tuning/victory.coefficient.3/label | B36: rule.tuning.victory.coefficient.3 | C36: victory · coefficient 3 | D36: victory · coefficient 3 | E36: string | F36: probability or multiplier | I36: READ ONLY
A37: /tuning/victory.coefficient.3/description | B37: rule.tuning.victory.coefficient.3 | C37: victory · coefficient 3 | D37: Coefficient in: (8 + state.depth * 2) * 0.85 * (state.encounterReward?.c | E37: string | F37: probability or multiplier | I37: READ ONLY
A38: /tuning/victory.coefficient.3/unit | B38: rule.tuning.victory.coefficient.3 | C38: victory · coefficient 3 | D38: probability or multiplier | E38: string | F38: probability or multiplier | I38: READ ONLY
A39: /tuning/victory.coefficient.3/min | B39: rule.tuning.victory.coefficient.3 | C39: victory · coefficient 3 | D39: 0 | E39: number | F39: probability or multiplier | G39: 0 | H39: 1 | I39: READ ONLY
A40: /tuning/victory.coefficient.3/max | B40: rule.tuning.victory.coefficient.3 | C40: victory · coefficient 3 | D40: 1 | E40: number | F40: probability or multiplier | G40: 0 | H40: 1 | I40: READ ONLY
A41: /tuning/victory.coefficient.3/integer | B41: rule.tuning.victory.coefficient.3 | C41: victory · coefficient 3 | D41: FALSE | E41: boolean | F41: probability or multiplier | I41: READ ONLY
A42: /tuning/victory.coefficient.4/value | B42: rule.tuning.victory.coefficient.4 | C42: victory · coefficient 4 | D42: 2 | E42: number | F42: count or coefficient | G42: 1 | H42: 100 | I42: Coefficient in: unt || 1) * (e.stronghold ? 2 : e.boss ? 1.35 : e.elite ? 1.2 : 1),
A43: /tuning/victory.coefficient.4/category | B43: rule.tuning.victory.coefficient.4 | C43: victory · coefficient 4 | D43: Progression | E43: string | F43: count or coefficient | I43: READ ONLY
...

Sheet Slots
A1: Stable field ID | B1: Entity ID | C1: Field / label | D1: Value (edit blue cells) | E1: Type | F1: Unit | G1: Minimum | H1: Maximum | I1: Notes
A2: /slots/types/0 | B2: rule.slots.types | C2: 0 | D2: attack | E2: string | I2: READ ONLY
A3: /slots/types/1 | B3: rule.slots.types | C3: 1 | D3: magic | E3: string | I3: READ ONLY
A4: /slots/types/2 | B4: rule.slots.types | C4: 2 | D4: poison | E4: string | I4: READ ONLY
A5: /slots/types/3 | B5: rule.slots.types | C5: 3 | D5: stimulant | E5: string | I5: READ ONLY
A6: /slots/types/4 | B6: rule.slots.types | C6: 4 | D6: heal | E6: string | I6: READ ONLY
A7: /slots/types/5 | B7: rule.slots.types | C7: 5 | D7: block | E7: string | I7: READ ONLY
A8: /slots/types/6 | B8: rule.slots.types | C8: 6 | D8: stun | E8: string | I8: READ ONLY
A9: /slots/types/7 | B9: rule.slots.types | C9: 7 | D9: class | E9: string | I9: READ ONLY
A10: /slots/types/8 | B10: rule.slots.types | C10: 8 | D10: blank | E10: string | I10: READ ONLY
A11: /slots/icons/attack | B11: rule.slots.icons | C11: attack | D11: sword | E11: string | I11: READ ONLY
A12: /slots/icons/magic | B12: rule.slots.icons | C12: magic | D12: magic | E12: string | I12: READ ONLY
A13: /slots/icons/poison | B13: rule.slots.icons | C13: poison | D13: poison | E13: string | I13: READ ONLY
... A21: /slots/icons/blank | B21: rule.slots.icons | C21: blank | D21: blank | E21: string | I21: READ ONLY
A22: /slots/power/poison | B22: rule.slots.power | C22: poison | D22: 1 | E22: number | G22: 0 | H22: 100000
A23: /slots/power/stimulant | B23: rule.slots.power | C23: stimulant | D23: 1 | E23: number | G23: 0 | H23: 100000
A24: /slots/power/heal | B24: rule.slots.power | C24: heal | D24: 2 | E24: number | G24: 0 | H24: 100000
A25: /slots/power/block | B25: rule.slots.power | C25: block | D25: 1 | E25: number | G25: 0 | H25: 100000
A26: /slots/power/stun | B26: rule.slots.power | C26: stun | D26: 1 | E26: number | G26: 0 | H26: 100000
A27: /slots/power/class | B27: rule.slots.power | C27: class | D27: 0 | E27: number | G27: 0 | H27: 100000
A28: /slots/power/blank | B28: rule.slots.power | C28: blank | D28: 0 | E28: number | G28: 0 | H28: 100000
A29: /slots/attackPower/0 | B29: rule.slots.attackPower | C29: 0 | D29: 0 | E29: number | G29: 0 | H29: 100000
A30: /slots/attackPower/1 | B30: rule.slots.attackPower | C30: 1 | D30: 2 | E30: number | G30: 0 | H30: 100000
A31: /slots/attackPower/2 | B31: rule.slots.attackPower | C31: 2 | D31: 4 | E31: number | G31: 0 | H31: 100000
A32: /slots/attackPower/3 | B32: rule.slots.attackPower | C32: 3 | D32: 7 | E32: number | G32: 0 | H32: 100000
A33: /slots/attackPower/4 | B33: rule.slots.attackPower | C33: 4 | D33: 11 | E33: number | G33: 0 | H33: 100000
... A41: /slots/criticalMultipliers/3 | B41: rule.slots.criticalMultipliers | C41: 3 | D41: 4 | E41: number | G41: 0 | H41: 100000

Sheet Classes
A1: Stable field ID | B1: Entity ID | C1: Field / label | D1: Value (edit blue cells) | E1: Type | F1: Unit | G1: Minimum | H1: Maximum | I1: Notes
A2: /classes/fighter/id | B2: class.fighter | C2: id | D2: class.fighter | E2: string | I2: READ ONLY
A3: /classes/fighter/name | B3: class.fighter | C3: name | D3: Tank | E3: string
A4: /classes/fighter/maxHp | B4: class.fighter | C4: maxHp | D4: 44 | E4: number | F4: HP | G4: 1 | H4: 100000
A5: /classes/fighter/last/0/type | B5: class.fighter | C5: last · 0 · type | D5: attack | E5: string | I5: READ ONLY
A6: /classes/fighter/last/0/tier | B6: class.fighter | C6: last · 0 · tier | D6: 1 | E6: number | F6: tier | G6: 1 | H6: 4 | I6: READ ONLY
A7: /classes/fighter/last/1/type | B7: class.fighter | C7: last · 1 · type | D7: block | E7: string | I7: READ ONLY
A8: /classes/fighter/last/1/tier | B8: class.fighter | C8: last · 1 · tier | D8: 1 | E8: number | F8: tier | G8: 1 | H8: 4 | I8: READ ONLY
A9: /classes/fighter/last/2/type | B9: class.fighter | C9: last · 2 · type | D9: blank | E9: string | I9: READ ONLY
A10: /classes/fighter/last/2/tier | B10: class.fighter | C10: last · 2 · tier | D10: 1 | E10: number | F10: tier | G10: 1 | H10: 4 | I10: READ ONLY
A11: /classes/healer/id | B11: class.healer | C11: id | D11: class.healer | E11: string | I11: READ ONLY
A12: /classes/healer/name | B12: class.healer | C12: name | D12: Healer | E12: string
A13: /classes/healer/maxHp | B13: class.healer | C13: maxHp | D13: 32 | E13: number | F13: HP | G13: 1 | H13: 100000
A14: /classes/healer/last/0/type | B14: class.healer | C14: last · 0 · type | D14: heal | E14: string | I14: READ ONLY
A15: /classes/healer/last/0/tier | B15: class.healer | C15: last · 0 · tier | D15: 1 | E15: number | F15: tier | G15: 1 | H15: 4 | I15: READ ONLY
A16: /classes/healer/last/1/type | B16: class.healer | C16: last · 1 · type | D16: heal | E16: string | I16: READ ONLY
A17: /classes/healer/last/1/tier | B17: class.healer | C17: last · 1 · tier | D17: 2 | E17: number | F17: tier | G17: 1 | H17: 4 | I17: READ ONLY
A18: /classes/healer/last/2/type | B18: class.healer | C18: last · 2 · type | D18: blank | E18: string | I18: READ ONLY
A19: /classes/healer/last/2/tier | B19: class.healer | C19: last · 2 · tier | D19: 1 | E19: number | F19: tier | G19: 1 | H19: 4 | I19: READ ONLY
A20: /classes/rogue/id | B20: class.rogue | C20: id | D20: class.rogue | E20: string | I20: READ ONLY
A21: /classes/rogue/name | B21: class.rogue | C21: name | D21: Rogue | E21: string
A22: /classes/rogue/maxHp | B22: class.rogue | C22: maxHp | D22: 26 | E22: number | F22: HP | G22: 1 | H22: 100000
A23: /classes/rogue/last/0/type | B23: class.rogue | C23: last · 0 · type | D23: attack | E23: string | I23: READ ONLY
A24: /classes/rogue/last/0/tier | B24: class.rogue | C24: last · 0 · tier | D24: 1 | E24: number | F24: tier | G24: 1 | H24: 4 | I24: READ ONLY
A25: /classes/rogue/last/1/type | B25: class.rogue | C25: last · 1 · type | D25: attack | E25: string | I25: READ ONLY
A26: /classes/rogue/last/1/tier | B26: class.rogue | C26: last · 1 · tier | D26: 3 | E26: number | F26: tier | G26: 1 | H26: 4 | I26: READ ONLY
A27: /classes/rogue/last/2/type | B27: class.rogue | C27: last · 2 · type | D27: blank | E27: string | I27: READ ONLY
A28: /classes/rogue/last/2/tier | B28: class.rogue | C28: last · 2 · tier | D28: 1 | E28: number | F28: tier | G28: 1 | H28: 4 | I28: READ ONLY
A29: /classes/mage/id | B29: class.mage | C29: id | D29: class.mage | E29: string | I29: READ ONLY
A30: /classes/mage/name | B30: class.mage | C30: name | D30: Mage | E30: string
A31: /classes/mage/maxHp | B31: class.mage | C31: maxHp | D31: 28 | E31: number | F31: HP | G31: 1 | H31: 100000
A32: /classes/mage/last/0/type | B32: class.mage | C32: last · 0 · type | D32: magic | E32: string | I32: READ ONLY
A33: /classes/mage/last/0/tier | B33: class.mage | C33: last · 0 · tier | D33: 1 | E33: number | F33: tier | G33: 1 | H33: 4 | I33: READ ONLY
A34: /classes/mage/last/1/type | B34: class.mage | C34: last · 1 · type | D34: stimulant | E34: string | I34: READ ONLY
A35: /classes/mage/last/1/tier | B35: class.mage | C35: last · 1 · tier | D35: 1 | E35: number | F35: tier | G35: 1 | H35: 4 | I35: READ ONLY
A36: /classes/mage/last/2/type | B36: class.mage | C36: last · 2 · type | D36: blank | E36: string | I36: READ ONLY
A37: /classes/mage/last/2/tier | B37: class.mage | C37: last · 2 · tier | D37: 1 | E37: number | F37: tier | G37: 1 | H37: 4 | I37: READ ONLY

Sheet Reels
A1: Stable field ID | B1: Entity ID | C1: Field / label | D1: Value (edit blue cells) | E1: Type | F1: Unit | G1: Minimum | H1: Maximum | I1: Notes
A2: /classes/fighter/reels/0/0/type | B2: class.fighter | C2: reels · 0 · 0 · type | D2: attack | E2: string
A3: /classes/fighter/reels/0/0/tier | B3: class.fighter | C3: reels · 0 · 0 · tier | D3: 1 | E3: number | F3: tier | G3: 1 | H3: 4
A4: /classes/fighter/reels/0/0/weight | B4: class.fighter | C4: reels · 0 · 0 · weight | D4: 9 | E4: number | F4: relative weight | G4: 0.0001 | H4: 100000
A5: /classes/fighter/reels/0/1/type | B5: class.fighter | C5: reels · 0 · 1 · type | D5: attack | E5: string
A6: /classes/fighter/reels/0/1/tier | B6: class.fighter | C6: reels · 0 · 1 · tier | D6: 2 | E6: number | F6: tier | G6: 1 | H6: 4
A7: /classes/fighter/reels/0/1/weight | B7: class.fighter | C7: reels · 0 · 1 · weight | D7: 5 | E7: number | F7: relative weight | G7: 0.0001 | H7: 100000
A8: /classes/fighter/reels/0/2/type | B8: class.fighter | C8: reels · 0 · 2 · type | D8: block | E8: string
A9: /classes/fighter/reels/0/2/tier | B9: class.fighter | C9: reels · 0 · 2 · tier | D9: 1 | E9: number | F9: tier | G9: 1 | H9: 4
A10: /classes/fighter/reels/0/2/weight | B10: class.fighter | C10: reels · 0 · 2 · weight | D10: 7 | E10: number | F10: relative weight | G10: 0.0001 | H10: 100000
A11: /classes/fighter/reels/0/3/type | B11: class.fighter | C11: reels · 0 · 3 · type | D11: block | E11: string
A12: /classes/fighter/reels/0/3/tier | B12: class.fighter | C12: reels · 0 · 3 · tier | D12: 2 | E12: number | F12: tier | G12: 1 | H12: 4
A13: /classes/fighter/reels/0/3/weight | B13: class.fighter | C13: reels · 0 · 3 · weight | D13: 3 | E13: number | F13: relative weight | G13: 0.0001 | H13: 100000
A14: /classes/fighter/reels/0/4/type | B14: class.fighter | C14: reels · 0 · 4 · type | D14: heal | E14: string
A15: /classes/fighter/reels/0/4/tier | B15: class.fighter | C15: reels · 0 · 4 · tier | D15: 1 | E15: number | F15: tier | G15: 1 | H15: 4
A16: /classes/fighter/reels/0/4/weight | B16: class.fighter | C16: reels · 0 · 4 · weight | D16: 1 | E16: number | F16: relative weight | G16: 0.0001 | H16: 100000
A17: /classes/fighter/reels/0/5/type | B17: class.fighter | C17: reels · 0 · 5 · type | D17: blank | E17: string
A18: /classes/fighter/reels/0/5/tier | B18: class.fighter | C18: reels · 0 · 5 · tier | D18: 1 | E18: number | F18: tier | G18: 1 | H18: 4
A19: /classes/fighter/reels/0/5/weight | B19: class.fighter | C19: reels · 0 · 5 · weight | D19: 5 | E19: number | F19: relative weight | G19: 0.0001 | H19: 100000
A20: /classes/fighter/reels/1/0/type | B20: class.fighter | C20: reels · 1 · 0 · type | D20: attack | E20: string
A21: /classes/fighter/reels/1/0/tier | B21: class.fighter | C21: reels · 1 · 0 · tier | D21: 1 | E21: number | F21: tier | G21: 1 | H21: 4
A22: /classes/fighter/reels/1/0/weight | B22: class.fighter | C22: reels · 1 · 0 · weight | D22: 9 | E22: number | F22: relative weight | G22: 0.0001 | H22: 100000
A23: /classes/fighter/reels/1/1/type | B23: class.fighter | C23: reels · 1 · 1 · type | D23: attack | E23: string
A24: /classes/fighter/reels/1/1/tier | B24: class.fighter | C24: reels · 1 · 1 · tier | D24: 2 | E24: number | F24: tier | G24: 1 | H24: 4
A25: /classes/fighter/reels/1/1/weight | B25: class.fighter | C25: reels · 1 · 1 · weight | D25: 5 | E25: number | F25: relative weight | G25: 0.0001 | H25: 100000
A26: /classes/fighter/reels/1/2/type | B26: class.fighter | C26: reels · 1 · 2 · type | D26: block | E26: string
A27: /classes/fighter/reels/1/2/tier | B27: class.fighter | C27: reels · 1 · 2 · tier | D27: 1 | E27: number | F27: tier | G27: 1 | H27: 4
A28: /classes/fighter/reels/1/2/weight | B28: class.fighter | C28: reels · 1 · 2 · weight | D28: 7 | E28: number | F28: relative weight | G28: 0.0001 | H28: 100000
A29: /classes/fighter/reels/1/3/type | B29: class.fighter | C29: reels · 1 · 3 · type | D29: block | E29: string
A30: /classes/fighter/reels/1/3/tier | B30: class.fighter | C30: reels · 1 · 3 · tier | D30: 2 | E30: number | F30: tier | G30: 1 | H30: 4
A31: /classes/fighter/reels/1/3/weight | B31: class.fighter | C31: reels · 1 · 3 · weight | D31: 3 | E31: number | F31: relative weight | G31: 0.0001 | H31: 100000
A32: /classes/fighter/reels/1/4/type | B32: class.fighter | C32: reels · 1 · 4 · type | D32: heal | E32: string
A33: /classes/fighter/reels/1/4/tier | B33: class.fighter | C33: reels · 1 · 4 · tier | D33: 1 | E33: number | F33: tier | G33: 1 | H33: 4
A34: /classes/fighter/reels/1/4/weight | B34: class.fighter | C34: reels · 1 · 4 · weight | D34: 1 | E34: number | F34: relative weight | G34: 0.0001 | H34: 100000
A35: /classes/fighter/reels/1/5/type | B35: class.fighter | C35: reels · 1 · 5 · type | D35: blank | E35: string
A36: /classes/fighter/reels/1/5/tier | B36: class.fighter | C36: reels · 1 · 5 · tier | D36: 1 | E36: number | F36: tier | G36: 1 | H36: 4
A37: /classes/fighter/reels/1/5/weight | B37: class.fighter | C37: reels · 1 · 5 · weight | D37: 5 | E37: number | F37: relative weight | G37: 0.0001 | H37: 100000
A38: /classes/fighter/reels/1/6/type | B38: class.fighter | C38: reels · 1 · 6 · type | D38: class | E38: string
A39: /classes/fighter/reels/1/6/tier | B39: class.fighter | C39: reels · 1 · 6 · tier | D39: 1 | E39: number | F39: tier | G39: 1 | H39: 4
A40: /classes/fighter/reels/1/6/weight | B40: class.fighter | C40: reels · 1 · 6 · weight | D40: 3 | E40: number | F40: relative weight | G40: 0.0001 | H40: 100000
...

Sheet Items
A1: Stable field ID | B1: Entity ID | C1: Field / label | D1: Value (edit blue cells) | E1: Type | F1: Unit | G1: Minimum | H1: Maximum | I1: Notes
A2: /items/potion/name | B2: item.potion | C2: name | D2: Healing tonic | E2: string
A3: /items/potion/icon | B3: item.potion | C3: icon | D3: potion | E3: string
A4: /items/potion/brief | B4: item.potion | C4: brief | D4: {heal} HP | E4: string
A5: /items/potion/description | B5: item.potion | C5: description | D5: Restore {heal} HP to the selected living hero. | E5: string
A6: /items/potion/id | B6: item.potion | C6: id | D6: item.potion | E6: string | I6: READ ONLY
A7: /items/potion/heal | B7: item.potion | C7: heal | D7: 16 | E7: number | G7: 0 | H7: 100000
A8: /items/bomb/name | B8: item.bomb | C8: name | D8: Ink bomb | E8: string
A9: /items/bomb/icon | B9: item.bomb | C9: icon | D9: bomb | E9: string
A10: /items/bomb/brief | B10: item.bomb | C10: brief | D10: Roll damage + poison | E10: string
A11: /items/bomb/combat | B11: item.bomb | C11: combat | D11: TRUE | E11: boolean
A12: /items/bomb/description | B12: item.bomb | C12: description | D12: Roll three reels for damage and poison against the selected enemy. Three alike can crit. | E12: string
A13: /items/bomb/id | B13: item.bomb | C13: id | D13: item.bomb | E13: string | I13: READ ONLY
A14: /items/ward/name | B14: item.ward | C14: name | D14: Paper ward | E14: string
A15: /items/ward/icon | B15: item.ward | C15: icon | D15: ward | E15: string
A16: /items/ward/brief | B16: item.ward | C16: brief | D16: {block} team block | E16: string
A17: /items/ward/combat | B17: item.ward | C17: combat | D17: TRUE | E17: boolean
A18: /items/ward/description | B18: item.ward | C18: description | D18: Add {block} shared block for this battle. | E18: string
A19: /items/ward/id | B19: item.ward | C19: id | D19: item.ward | E19: string | I19: READ ONLY
A20: /items/ward/block | B20: item.ward | C20: block | D20: 5 | E20: number | G20: 0 | H20: 100000
A21: /items/antidote/name | B21: item.antidote | C21: name | D21: Antidote | E21: string
A22: /items/antidote/icon | B22: item.antidote | C22: icon | D22: antidote | E22: string
A23: /items/antidote/brief | B23: item.antidote | C23: brief | D23: Cure poison | E23: string
A24: /items/antidote/description | B24: item.antidote | C24: description | D24: Remove poison from the selected living hero. | E24: string
A25: /items/antidote/id | B25: item.antidote | C25: id | D25: item.antidote | E25: string | I25: READ ONLY
A26: /items/bandage/name | B26: item.bandage | C26: name | D26: Bandage | E26: string
A27: /items/bandage/icon | B27: item.bandage | C27: icon | D27: bandage | E27: string
A28: /items/bandage/brief | B28: item.bandage | C28: brief | D28: {heal} HP | E28: string
A29: /items/bandage/description | B29: item.bandage | C29: description | D29: Restore {heal} HP to the selected living hero. | E29: string
A30: /items/bandage/id | B30: item.bandage | C30: id | D30: item.bandage | E30: string | I30: READ ONLY
A31: /items/bandage/heal | B31: item.bandage | C31: heal | D31: 8 | E31: number | G31: 0 | H31: 100000
A32: /items/salve/name | B32: item.salve | C32: name | D32: Mending salve | E32: string
A33: /items/salve/icon | B33: item.salve | C33: icon | D33: salve | E33: string
A34: /items/salve/brief | B34: item.salve | C34: brief | D34: {heal} HP to everyone | E34: string
A35: /items/salve/description | B35: item.salve | C35: description | D35: Restore {heal} HP to every living party member. | E35: string
A36: /items/salve/id | B36: item.salve | C36: id | D36: item.salve | E36: string | I36: READ ONLY
A37: /items/salve/heal | B37: item.salve | C37: heal | D37: 6 | E37: number | G37: 0 | H37: 100000
A38: /items/ember/name | B38: item.ember | C38: name | D38: Ember draught | E38: string
A39: /items/ember/icon | B39: item.ember | C39: icon | D39: flame | E39: string
A40: /items/ember/brief | B40: item.ember | C40: brief | D40: Damage + protection | E40: string
...

Sheet Equipment
A1: Stable field ID | B1: Entity ID | C1: Field / label | D1: Value (edit blue cells) | E1: Type | F1: Unit | G1: Minimum | H1: Maximum | I1: Notes
A2: /equipment/ironSignet/name | B2: equipment.ironSignet | C2: name | D2: Iron Signet | E2: string
A3: /equipment/ironSignet/icon | B3: equipment.ironSignet | C3: icon | D3: rage | E3: string
A4: /equipment/ironSignet/job | B4: equipment.ironSignet | C4: job | D4: fighter | E4: string
A5: /equipment/ironSignet/brief | B5: equipment.ironSignet | C5: brief | D5: +{attack} blade damage | E5: string
A6: /equipment/ironSignet/description | B6: equipment.ironSignet | C6: description | D6: Tank equipment. Every damaging roll gains {attack} damage. | E6: string
A7: /equipment/ironSignet/attack | B7: equipment.ironSignet | C7: attack | D7: 2 | E7: number | G7: 0 | H7: 100000
A8: /equipment/ironSignet/id | B8: equipment.ironSignet | C8: id | D8: equipment.ironSignet | E8: string | I8: READ ONLY
A9: /equipment/bulwarkBadge/name | B9: equipment.bulwarkBadge | C9: name | D9: Bulwark Badge | E9: string
A10: /equipment/bulwarkBadge/icon | B10: equipment.bulwarkBadge | C10: icon | D10: block | E10: string
A11: /equipment/bulwarkBadge/job | B11: equipment.bulwarkBadge | C11: job | D11: fighter | E11: string
A12: /equipment/bulwarkBadge/brief | B12: equipment.bulwarkBadge | C12: brief | D12: +{guard} opening armour | E12: string
A13: /equipment/bulwarkBadge/description | B13: equipment.bulwarkBadge | C13: description | D13: Tank equipment. Start fights with {guard} team block; resist {defence} damage per incoming hit. | E13: string
A14: /equipment/bulwarkBadge/guard | B14: equipment.bulwarkBadge | C14: guard | D14: 3 | E14: number | G14: 0 | H14: 100000
A15: /equipment/bulwarkBadge/defence | B15: equipment.bulwarkBadge | C15: defence | D15: 1 | E15: number | G15: 0 | H15: 100000
A16: /equipment/bulwarkBadge/id | B16: equipment.bulwarkBadge | C16: id | D16: equipment.bulwarkBadge | E16: string | I16: READ ONLY
A17: /equipment/glassRosary/name | B17: equipment.glassRosary | C17: name | D17: Glass Rosary | E17: string
A18: /equipment/glassRosary/icon | B18: equipment.glassRosary | C18: icon | D18: heal | E18: string
A19: /equipment/glassRosary/job | B19: equipment.glassRosary | C19: job | D19: healer | E19: string
A20: /equipment/glassRosary/brief | B20: equipment.glassRosary | C20: brief | D20: +{heal} healing | E20: string
A21: /equipment/glassRosary/description | B21: equipment.glassRosary | C21: description | D21: Healer equipment. Add {heal} HP to healing rolls. | E21: string
A22: /equipment/glassRosary/heal | B22: equipment.glassRosary | C22: heal | D22: 2 | E22: number | G22: 0 | H22: 100000
A23: /equipment/glassRosary/id | B23: equipment.glassRosary | C23: id | D23: equipment.glassRosary | E23: string | I23: READ ONLY
A24: /equipment/mercyBell/name | B24: equipment.mercyBell | C24: name | D24: Mercy Bell | E24: string
A25: /equipment/mercyBell/icon | B25: equipment.mercyBell | C25: icon | D25: blessing | E25: string
A26: /equipment/mercyBell/job | B26: equipment.mercyBell | C26: job | D26: healer | E26: string
A27: /equipment/mercyBell/brief | B27: equipment.mercyBell | C27: brief | D27: A little sanctuary | E27: string
A28: /equipment/mercyBell/description | B28: equipment.mercyBell | C28: description | D28: Healer equipment. Every roll heals the party by {teamHeal} and adds {block} team block. | E28: string
A29: /equipment/mercyBell/teamHeal | B29: equipment.mercyBell | C29: teamHeal | D29: 1 | E29: number | G29: 0 | H29: 100000
A30: /equipment/mercyBell/block | B30: equipment.mercyBell | C30: block | D30: 1 | E30: number | G30: 0 | H30: 100000
A31: /equipment/mercyBell/id | B31: equipment.mercyBell | C31: id | D31: equipment.mercyBell | E31: string | I31: READ ONLY
A32: /equipment/silentBoots/name | B32: equipment.silentBoots | C32: name | D32: Silent Boots | E32: string
A33: /equipment/silentBoots/icon | B33: equipment.silentBoots | C33: icon | D33: flurry | E33: string
A34: /equipment/silentBoots/job | B34: equipment.silentBoots | C34: job | D34: rogue | E34: string
A35: /equipment/silentBoots/brief | B35: equipment.silentBoots | C35: brief | D35: Every {stunEveryOrdinal} roll stuns | E35: string
A36: /equipment/silentBoots/description | B36: equipment.silentBoots | C36: description | D36: Rogue equipment. +{attack} damage; every {stunEveryOrdinal} roll stuns the target. | E36: string
A37: /equipment/silentBoots/attack | B37: equipment.silentBoots | C37: attack | D37: 1 | E37: number | G37: 0 | H37: 100000
A38: /equipment/silentBoots/stunEvery | B38: equipment.silentBoots | C38: stunEvery | D38: 4 | E38: number | G38: 0 | H38: 100000
A39: /equipment/silentBoots/id | B39: equipment.silentBoots | C39: id | D39: equipment.silentBoots | E39: string | I39: READ ONLY
A40: /equipment/serpentPin/name | B40: equipment.serpentPin | C40: name | D40: Serpent Pin | E40: string
...

Sheet Artefacts
A1: Stable field ID | B1: Entity ID | C1: Field / label | D1: Value (edit blue cells) | E1: Type | F1: Unit | G1: Minimum | H1: Maximum | I1: Notes
A2: /artefacts/0/key | B2: artefact.attack | C2: key | D2: attack | E2: string
A3: /artefacts/0/name | B3: artefact.attack | C3: name | D3: Fang of the Margin | E3: string
A4: /artefacts/0/base | B4: artefact.attack | C4: base | D4: 1 | E4: number | G4: 0 | H4: 100000
A5: /artefacts/0/scale | B5: artefact.attack | C5: scale | D5: 0.6 | E5: number | G5: 0 | H5: 100000
A6: /artefacts/0/id | B6: artefact.attack | C6: id | D6: artefact.attack | E6: string | I6: READ ONLY
A7: /artefacts/1/key | B7: artefact.heal | C7: key | D7: heal | E7: string
A8: /artefacts/1/name | B8: artefact.heal | C8: name | D8: The Glass Tear | E8: string
A9: /artefacts/1/base | B9: artefact.heal | C9: base | D9: 1 | E9: number | G9: 0 | H9: 100000
A10: /artefacts/1/scale | B10: artefact.heal | C10: scale | D10: 0.5 | E10: number | G10: 0 | H10: 100000
A11: /artefacts/1/id | B11: artefact.heal | C11: id | D11: artefact.heal | E11: string | I11: READ ONLY
A12: /artefacts/2/key | B12: artefact.block | C12: key | D12: block | E12: string
A13: /artefacts/2/name | B13: artefact.block | C13: name | D13: Iron Pennant | E13: string
A14: /artefacts/2/base | B14: artefact.block | C14: base | D14: 1 | E14: number | G14: 0 | H14: 100000
A15: /artefacts/2/scale | B15: artefact.block | C15: scale | D15: 0.5 | E15: number | G15: 0 | H15: 100000
A16: /artefacts/2/id | B16: artefact.block | C16: id | D16: artefact.block | E16: string | I16: READ ONLY
A17: /artefacts/3/key | B17: artefact.gold | C17: key | D17: gold | E17: string
A18: /artefacts/3/name | B18: artefact.gold | C18: name | D18: Lucky Farthing | E18: string
A19: /artefacts/3/base | B19: artefact.gold | C19: base | D19: 10 | E19: number | G19: 0 | H19: 100000
A20: /artefacts/3/scale | B20: artefact.gold | C20: scale | D20: 3 | E20: number | G20: 0 | H20: 100000
A21: /artefacts/3/id | B21: artefact.gold | C21: id | D21: artefact.gold | E21: string | I21: READ ONLY
A22: /artefacts/4/key | B22: artefact.guard | C22: key | D22: guard | E22: string
A23: /artefacts/4/name | B23: artefact.guard | C23: name | D23: Ember Seal | E23: string
A24: /artefacts/4/base | B24: artefact.guard | C24: base | D24: 1 | E24: number | G24: 0 | H24: 100000
A25: /artefacts/4/scale | B25: artefact.guard | C25: scale | D25: 0.5 | E25: number | G25: 0 | H25: 100000
A26: /artefacts/4/id | B26: artefact.guard | C26: id | D26: artefact.guard | E26: string | I26: READ ONLY
A27: /artefacts/5/key | B27: artefact.revive | C27: key | D27: revive | E27: string
A28: /artefacts/5/name | B28: artefact.revive | C28: name | D28: Revive Stone | E28: string
A29: /artefacts/5/base | B29: artefact.revive | C29: base | D29: 1 | E29: number | G29: 0 | H29: 100000
A30: /artefacts/5/scale | B30: artefact.revive | C30: scale | D30: 0 | E30: number | G30: 0 | H30: 100000
A31: /artefacts/5/id | B31: artefact.revive | C31: id | D31: artefact.revive | E31: string | I31: READ ONLY
A32: /tuning/makeArtefact.name.1/value | B32: rule.tuning.makeArtefact.name.1 | C32: makeArtefact · name 1 | D32: 3 | E32: number | F32: count or coefficient | G32: 0 | H32: 3 | I32: Coefficient in: ["I", "II", "III", "IV"][Math.min(3, Math.floor((depth - 1) / 3))], k
A33: /tuning/makeArtefact.name.1/category | B33: rule.tuning.makeArtefact.name.1 | C33: makeArtefact · name 1 | D33: Artefacts | E33: string | F33: count or coefficient | I33: READ ONLY
A34: /tuning/makeArtefact.name.1/label | B34: rule.tuning.makeArtefact.name.1 | C34: makeArtefact · name 1 | D34: makeArtefact · name 1 | E34: string | F34: count or coefficient | I34: READ ONLY
A35: /tuning/makeArtefact.name.1/description | B35: rule.tuning.makeArtefact.name.1 | C35: makeArtefact · name 1 | D35: Coefficient in: ["I", "II", "III", "IV"][Math.min(3, Math.floor((depth - 1) / 3))], k | E35: string | F35: count or coefficient | I35: READ ONLY
A36: /tuning/makeArtefact.name.1/unit | B36: rule.tuning.makeArtefact.name.1 | C36: makeArtefact · name 1 | D36: count or coefficient | E36: string | F36: count or coefficient | I36: READ ONLY
A37: /tuning/makeArtefact.name.1/min | B37: rule.tuning.makeArtefact.name.1 | C37: makeArtefact · name 1 | D37: 0 | E37: number | F37: count or coefficient | G37: 0 | H37: 3 | I37: READ ONLY
A38: /tuning/makeArtefact.name.1/max | B38: rule.tuning.makeArtefact.name.1 | C38: makeArtefact · name 1 | D38: 100 | E38: number | F38: count or coefficient | G38: 0 | H38: 3 | I38: READ ONLY
A39: /tuning/makeArtefact.name.1/integer | B39: rule.tuning.makeArtefact.name.1 | C39: makeArtefact · name 1 | D39: TRUE | E39: boolean | F39: count or coefficient | I39: READ ONLY
A40: /tuning/makeArtefact.name.2/value | B40: rule.tuning.makeArtefact.name.2 | C40: makeArtefact · name 2 | D40: 3 | E40: number | F40: count or coefficient | G40: 1 | H40: 100 | I40: Coefficient in: [Math.min(3, Math.floor((depth - 1) / 3))], key: t.key, power: Math.c
...

Sheet Enemies
A1: Stable field ID | B1: Entity ID | C1: Field / label | D1: Value (edit blue cells) | E1: Type | F1: Unit | G1: Minimum | H1: Maximum | I1: Notes
A2: /enemies/enemy.ink-rat/id | B2: enemy.ink-rat | C2: id | D2: enemy.ink-rat | E2: string | I2: READ ONLY
A3: /enemies/enemy.ink-rat/name | B3: enemy.ink-rat | C3: name | D3: The ink rat | E3: string
A4: /enemies/enemy.ink-rat/art | B4: enemy.ink-rat | C4: art | D4: rat | E4: string
A5: /enemies/enemy.ink-rat/minFloor | B5: enemy.ink-rat | C5: minFloor | D5: 1 | E5: number | G5: 1 | H5: 10
A6: /enemies/enemy.ink-rat/maxFloor | B6: enemy.ink-rat | C6: maxFloor | D6: 3 | E6: number | G6: 1 | H6: 10
A7: /enemies/enemy.ink-rat/hpMultiplier | B7: enemy.ink-rat | C7: hpMultiplier | D7: 1 | E7: number | G7: 0.0001 | H7: 100
A8: /enemies/enemy.ink-rat/damageMultiplier | B8: enemy.ink-rat | C8: damageMultiplier | D8: 1 | E8: number | G8: 0.0001 | H8: 100
A9: /enemies/enemy.ink-rat/frequencyOverride | B9: enemy.ink-rat | C9: frequencyOverride | D9: 0 | E9: number | G9: 0 | H9: 10
A10: /enemies/enemy.ink-rat/strikesOverride | B10: enemy.ink-rat | C10: strikesOverride | D10: 0 | E10: number | G10: 0 | H10: 10
A11: /enemies/enemy.ink-rat/reelSet | B11: enemy.ink-rat | C11: reelSet | D11: reel.enemy.rat | E11: string
A12: /enemies/enemy.margin-wraith/id | B12: enemy.margin-wraith | C12: id | D12: enemy.margin-wraith | E12: string | I12: READ ONLY
A13: /enemies/enemy.margin-wraith/name | B13: enemy.margin-wraith | C13: name | D13: Margin wraith | E13: string
A14: /enemies/enemy.margin-wraith/art | B14: enemy.margin-wraith | C14: art | D14: ghost | E14: string
A15: /enemies/enemy.margin-wraith/minFloor | B15: enemy.margin-wraith | C15: minFloor | D15: 1 | E15: number | G15: 1 | H15: 10
A16: /enemies/enemy.margin-wraith/maxFloor | B16: enemy.margin-wraith | C16: maxFloor | D16: 3 | E16: number | G16: 1 | H16: 10
A17: /enemies/enemy.margin-wraith/hpMultiplier | B17: enemy.margin-wraith | C17: hpMultiplier | D17: 1 | E17: number | G17: 0.0001 | H17: 100
A18: /enemies/enemy.margin-wraith/damageMultiplier | B18: enemy.margin-wraith | C18: damageMultiplier | D18: 1 | E18: number | G18: 0.0001 | H18: 100
A19: /enemies/enemy.margin-wraith/frequencyOverride | B19: enemy.margin-wraith | C19: frequencyOverride | D19: 0 | E19: number | G19: 0 | H19: 10
A20: /enemies/enemy.margin-wraith/strikesOverride | B20: enemy.margin-wraith | C20: strikesOverride | D20: 0 | E20: number | G20: 0 | H20: 10
A21: /enemies/enemy.margin-wraith/reelSet | B21: enemy.margin-wraith | C21: reelSet | D21: reel.enemy.ghost | E21: string
A22: /enemies/enemy.blotling/id | B22: enemy.blotling | C22: id | D22: enemy.blotling | E22: string | I22: READ ONLY
A23: /enemies/enemy.blotling/name | B23: enemy.blotling | C23: name | D23: Blotling | E23: string
A24: /enemies/enemy.blotling/art | B24: enemy.blotling | C24: art | D24: slime | E24: string
A25: /enemies/enemy.blotling/minFloor | B25: enemy.blotling | C25: minFloor | D25: 1 | E25: number | G25: 1 | H25: 10
A26: /enemies/enemy.blotling/maxFloor | B26: enemy.blotling | C26: maxFloor | D26: 3 | E26: number | G26: 1 | H26: 10
A27: /enemies/enemy.blotling/hpMultiplier | B27: enemy.blotling | C27: hpMultiplier | D27: 1 | E27: number | G27: 0.0001 | H27: 100
A28: /enemies/enemy.blotling/damageMultiplier | B28: enemy.blotling | C28: damageMultiplier | D28: 1 | E28: number | G28: 0.0001 | H28: 100
A29: /enemies/enemy.blotling/frequencyOverride | B29: enemy.blotling | C29: frequencyOverride | D29: 0 | E29: number | G29: 0 | H29: 10
A30: /enemies/enemy.blotling/strikesOverride | B30: enemy.blotling | C30: strikesOverride | D30: 0 | E30: number | G30: 0 | H30: 10
A31: /enemies/enemy.blotling/reelSet | B31: enemy.blotling | C31: reelSet | D31: reel.enemy.slime | E31: string
A32: /enemies/enemy.skeletal-warrior/id | B32: enemy.skeletal-warrior | C32: id | D32: enemy.skeletal-warrior | E32: string | I32: READ ONLY
A33: /enemies/enemy.skeletal-warrior/name | B33: enemy.skeletal-warrior | C33: name | D33: Skeletal warrior | E33: string
A34: /enemies/enemy.skeletal-warrior/art | B34: enemy.skeletal-warrior | C34: art | D34: skull | E34: string
A35: /enemies/enemy.skeletal-warrior/minFloor | B35: enemy.skeletal-warrior | C35: minFloor | D35: 1 | E35: number | G35: 1 | H35: 10
A36: /enemies/enemy.skeletal-warrior/maxFloor | B36: enemy.skeletal-warrior | C36: maxFloor | D36: 3 | E36: number | G36: 1 | H36: 10
A37: /enemies/enemy.skeletal-warrior/hpMultiplier | B37: enemy.skeletal-warrior | C37: hpMultiplier | D37: 1 | E37: number | G37: 0.0001 | H37: 100
A38: /enemies/enemy.skeletal-warrior/damageMultiplier | B38: enemy.skeletal-warrior | C38: damageMultiplier | D38: 1 | E38: number | G38: 0.0001 | H38: 100
A39: /enemies/enemy.skeletal-warrior/frequencyOverride | B39: enemy.skeletal-warrior | C39: frequencyOverride | D39: 0 | E39: number | G39: 0 | H39: 10
A40: /enemies/enemy.skeletal-warrior/strikesOverride | B40: enemy.skeletal-warrior | C40: strikesOverride | D40: 0 | E40: number | G40: 0 | H40: 10
...

Sheet World
A1: Stable field ID | B1: Entity ID | C1: Field / label | D1: Value (edit blue cells) | E1: Type | F1: Unit | G1: Minimum | H1: Maximum | I1: Notes
A2: /tuning/generateFloor.start.1/value | B2: rule.tuning.generateFloor.start.1 | C2: generateFloor · start 1 | D2: 7 | E2: number | F2: count or coefficient | G2: 7 | H2: 7 | I2: Coefficient in: Pity || 0, ) { const start = pos(1, 7), map = Array.from({ length: W *
A3: /tuning/generateFloor.start.1/category | B3: rule.tuning.generateFloor.start.1 | C3: generateFloor · start 1 | D3: World | E3: string | F3: count or coefficient | I3: READ ONLY
A4: /tuning/generateFloor.start.1/label | B4: rule.tuning.generateFloor.start.1 | C4: generateFloor · start 1 | D4: generateFloor · start 1 | E4: string | F4: count or coefficient | I4: READ ONLY
A5: /tuning/generateFloor.start.1/description | B5: rule.tuning.generateFloor.start.1 | C5: generateFloor · start 1 | D5: Coefficient in: Pity || 0, ) { const start = pos(1, 7), map = Array.from({ length: W * | E5: string | F5: count or coefficient | I5: READ ONLY
A6: /tuning/generateFloor.start.1/unit | B6: rule.tuning.generateFloor.start.1 | C6: generateFloor · start 1 | D6: count or coefficient | E6: string | F6: count or coefficient | I6: READ ONLY
A7: /tuning/generateFloor.start.1/min | B7: rule.tuning.generateFloor.start.1 | C7: generateFloor · start 1 | D7: 0 | E7: number | F7: count or coefficient | G7: 0 | H7: 0 | I7: READ ONLY
A8: /tuning/generateFloor.start.1/max | B8: rule.tuning.generateFloor.start.1 | C8: generateFloor · start 1 | D8: 100 | E8: number | F8: count or coefficient | G8: 100 | H8: 100 | I8: READ ONLY
A9: /tuning/generateFloor.start.1/integer | B9: rule.tuning.generateFloor.start.1 | C9: generateFloor · start 1 | D9: TRUE | E9: boolean | F9: count or coefficient | I9: READ ONLY
A10: /tuning/generateFloor.coefficient.1/value | B10: rule.tuning.generateFloor.coefficient.1 | C10: generateFloor · coefficient 1 | D10: 0.11 | E10: number | F10: probability or multiplier | G10: 0 | H10: 1 | I10: Coefficient in: os(x, y) !== start && Math.random() < 0.11) Object.assign(map[pos(x, y)]
A11: /tuning/generateFloor.coefficient.1/category | B11: rule.tuning.generateFloor.coefficient.1 | C11: generateFloor · coefficient 1 | D11: World | E11: string | F11: probability or multiplier | I11: READ ONLY
A12: /tuning/generateFloor.coefficient.1/label | B12: rule.tuning.generateFloor.coefficient.1 | C12: generateFloor · coefficient 1 | D12: generateFloor · coefficient 1 | E12: string | F12: probability or multiplier | I12: READ ONLY
A13: /tuning/generateFloor.coefficient.1/description | B13: rule.tuning.generateFloor.coefficient.1 | C13: generateFloor · coefficient 1 | D13: Coefficient in: os(x, y) !== start && Math.random() < 0.11) Object.assign(map[pos(x, y)] | E13: string | F13: probability or multiplier | I13: READ ONLY
A14: /tuning/generateFloor.coefficient.1/unit | B14: rule.tuning.generateFloor.coefficient.1 | C14: generateFloor · coefficient 1 | D14: probability or multiplier | E14: string | F14: probability or multiplier | I14: READ ONLY
A15: /tuning/generateFloor.coefficient.1/min | B15: rule.tuning.generateFloor.coefficient.1 | C15: generateFloor · coefficient 1 | D15: 0 | E15: number | F15: probability or multiplier | G15: 0 | H15: 1 | I15: READ ONLY
A16: /tuning/generateFloor.coefficient.1/max | B16: rule.tuning.generateFloor.coefficient.1 | C16: generateFloor · coefficient 1 | D16: 1 | E16: number | F16: probability or multiplier | G16: 0 | H16: 1 | I16: READ ONLY
A17: /tuning/generateFloor.coefficient.1/integer | B17: rule.tuning.generateFloor.coefficient.1 | C17: generateFloor · coefficient 1 | D17: FALSE | E17: boolean | F17: probability or multiplier | I17: READ ONLY
A18: /tuning/generateFloor.riverCount.1/value | B18: rule.tuning.generateFloor.riverCount.1 | C18: generateFloor · riverCount 1 | D18: 0.012 | E18: number | F18: probability or multiplier | G18: 0 | H18: 1 | I18: Coefficient in: andom(), riverCount = riverRoll < 0.012 ? 2 : riverRoll < 0.35 ? 1 : 0; for
A19: /tuning/generateFloor.riverCount.1/category | B19: rule.tuning.generateFloor.riverCount.1 | C19: generateFloor · riverCount 1 | D19: World | E19: string | F19: probability or multiplier | I19: READ ONLY
A20: /tuning/generateFloor.riverCount.1/label | B20: rule.tuning.generateFloor.riverCount.1 | C20: generateFloor · riverCount 1 | D20: generateFloor · riverCount 1 | E20: string | F20: probability or multiplier | I20: READ ONLY
A21: /tuning/generateFloor.riverCount.1/description | B21: rule.tuning.generateFloor.riverCount.1 | C21: generateFloor · riverCount 1 | D21: Coefficient in: andom(), riverCount = riverRoll < 0.012 ? 2 : riverRoll < 0.35 ? 1 : 0; for | E21: string | F21: probability or multiplier | I21: READ ONLY
A22: /tuning/generateFloor.riverCount.1/unit | B22: rule.tuning.generateFloor.riverCount.1 | C22: generateFloor · riverCount 1 | D22: probability or multiplier | E22: string | F22: probability or multiplier | I22: READ ONLY
A23: /tuning/generateFloor.riverCount.1/min | B23: rule.tuning.generateFloor.riverCount.1 | C23: generateFloor · riverCount 1 | D23: 0 | E23: number | F23: probability or multiplier | G23: 0 | H23: 1 | I23: READ ONLY
A24: /tuning/generateFloor.riverCount.1/max | B24: rule.tuning.generateFloor.riverCount.1 | C24: generateFloor · riverCount 1 | D24: 1 | E24: number | F24: probability or multiplier | G24: 0 | H24: 1 | I24: READ ONLY
A25: /tuning/generateFloor.riverCount.1/integer | B25: rule.tuning.generateFloor.riverCount.1 | C25: generateFloor · riverCount 1 | D25: FALSE | E25: boolean | F25: probability or multiplier | I25: READ ONLY
A26: /tuning/generateFloor.riverCount.2/value | B26: rule.tuning.generateFloor.riverCount.2 | C26: generateFloor · riverCount 2 | D26: 2 | E26: number | F26: count or coefficient | G26: 1 | H26: 2 | I26: Coefficient in: riverCount = riverRoll < 0.012 ? 2 : riverRoll < 0.35 ? 1 : 0; for (le
A27: /tuning/generateFloor.riverCount.2/category | B27: rule.tuning.generateFloor.riverCount.2 | C27: generateFloor · riverCount 2 | D27: World | E27: string | F27: count or coefficient | I27: READ ONLY
A28: /tuning/generateFloor.riverCount.2/label | B28: rule.tuning.generateFloor.riverCount.2 | C28: generateFloor · riverCount 2 | D28: generateFloor · riverCount 2 | E28: string | F28: count or coefficient | I28: READ ONLY
A29: /tuning/generateFloor.riverCount.2/description | B29: rule.tuning.generateFloor.riverCount.2 | C29: generateFloor · riverCount 2 | D29: Coefficient in: riverCount = riverRoll < 0.012 ? 2 : riverRoll < 0.35 ? 1 : 0; for (le | E29: string | F29: count or coefficient | I29: READ ONLY
A30: /tuning/generateFloor.riverCount.2/unit | B30: rule.tuning.generateFloor.riverCount.2 | C30: generateFloor · riverCount 2 | D30: count or coefficient | E30: string | F30: count or coefficient | I30: READ ONLY
A31: /tuning/generateFloor.riverCount.2/min | B31: rule.tuning.generateFloor.riverCount.2 | C31: generateFloor · riverCount 2 | D31: 0 | E31: number | F31: count or coefficient | G31: 1 | H31: 2 | I31: READ ONLY
A32: /tuning/generateFloor.riverCount.2/max | B32: rule.tuning.generateFloor.riverCount.2 | C32: generateFloor · riverCount 2 | D32: 100 | E32: number | F32: count or coefficient | G32: 1 | H32: 2 | I32: READ ONLY
A33: /tuning/generateFloor.riverCount.2/integer | B33: rule.tuning.generateFloor.riverCount.2 | C33: generateFloor · riverCount 2 | D33: TRUE | E33: boolean | F33: count or coefficient | I33: READ ONLY
A34: /tuning/generateFloor.riverCount.3/value | B34: rule.tuning.generateFloor.riverCount.3 | C34: generateFloor · riverCount 3 | D34: 0.35 | E34: number | F34: probability or multiplier | G34: 0 | H34: 1 | I34: Coefficient in: = riverRoll < 0.012 ? 2 : riverRoll < 0.35 ? 1 : 0; for (let stream = 0; strea
A35: /tuning/generateFloor.riverCount.3/category | B35: rule.tuning.generateFloor.riverCount.3 | C35: generateFloor · riverCount 3 | D35: World | E35: string | F35: probability or multiplier | I35: READ ONLY
A36: /tuning/generateFloor.riverCount.3/label | B36: rule.tuning.generateFloor.riverCount.3 | C36: generateFloor · riverCount 3 | D36: generateFloor · riverCount 3 | E36: string | F36: probability or multiplier | I36: READ ONLY
A37: /tuning/generateFloor.riverCount.3/description | B37: rule.tuning.generateFloor.riverCount.3 | C37: generateFloor · riverCount 3 | D37: Coefficient in: = riverRoll < 0.012 ? 2 : riverRoll < 0.35 ? 1 : 0; for (let stream = 0; strea | E37: string | F37: probability or multiplier | I37: READ ONLY
A38: /tuning/generateFloor.riverCount.3/unit | B38: rule.tuning.generateFloor.riverCount.3 | C38: generateFloor · riverCount 3 | D38: probability or multiplier | E38: string | F38: probability or multiplier | I38: READ ONLY
A39: /tuning/generateFloor.riverCount.3/min | B39: rule.tuning.generateFloor.riverCount.3 | C39: generateFloor · riverCount 3 | D39: 0 | E39: number | F39: probability or multiplier | G39: 0 | H39: 1 | I39: READ ONLY
A40: /tuning/generateFloor.riverCount.3/max | B40: rule.tuning.generateFloor.riverCount.3 | C40: generateFloor · riverCount 3 | D40: 1 | E40: number | F40: probability or multiplier | G40: 0 | H40: 1 | I40: READ ONLY
...

Sheet Loot
A1: Stable field ID | B1: Entity ID | C1: Field / label | D1: Value (edit blue cells) | E1: Type | F1: Unit | G1: Minimum | H1: Maximum | I1: Notes
A2: /tuning/treasureRoll.baseGold.1/value | B2: rule.tuning.treasureRoll.baseGold.1 | C2: treasureRoll · baseGold 1 | D2: 2 | E2: number | F2: count or coefficient | G2: 1 | H2: 100 | I2: Coefficient in: faces, faces, faces]), baseGold = 2 + state.depth, counts = {}, f
A3: /tuning/treasureRoll.baseGold.1/category | B3: rule.tuning.treasureRoll.baseGold.1 | C3: treasureRoll · baseGold 1 | D3: Loot | E3: string | F3: count or coefficient | I3: READ ONLY
A4: /tuning/treasureRoll.baseGold.1/label | B4: rule.tuning.treasureRoll.baseGold.1 | C4: treasureRoll · baseGold 1 | D4: treasureRoll · baseGold 1 | E4: string | F4: count or coefficient | I4: READ ONLY
A5: /tuning/treasureRoll.baseGold.1/description | B5: rule.tuning.treasureRoll.baseGold.1 | C5: treasureRoll · baseGold 1 | D5: Coefficient in: faces, faces, faces]), baseGold = 2 + state.depth, counts = {}, f | E5: string | F5: count or coefficient | I5: READ ONLY
A6: /tuning/treasureRoll.baseGold.1/unit | B6: rule.tuning.treasureRoll.baseGold.1 | C6: treasureRoll · baseGold 1 | D6: count or coefficient | E6: string | F6: count or coefficient | I6: READ ONLY
A7: /tuning/treasureRoll.baseGold.1/min | B7: rule.tuning.treasureRoll.baseGold.1 | C7: treasureRoll · baseGold 1 | D7: 0 | E7: number | F7: count or coefficient | G7: 1 | H7: 100 | I7: READ ONLY
A8: /tuning/treasureRoll.baseGold.1/max | B8: rule.tuning.treasureRoll.baseGold.1 | C8: treasureRoll · baseGold 1 | D8: 100 | E8: number | F8: count or coefficient | G8: 1 | H8: 100 | I8: READ ONLY
A9: /tuning/treasureRoll.baseGold.1/integer | B9: rule.tuning.treasureRoll.baseGold.1 | C9: treasureRoll · baseGold 1 | D9: TRUE | E9: boolean | F9: count or coefficient | I9: READ ONLY
A10: /tuning/treasureRoll.coefficient.1/value | B10: rule.tuning.treasureRoll.coefficient.1 | C10: treasureRoll · coefficient 1 | D10: 2 | E10: number | F10: count or coefficient | G10: 1 | H10: 100 | I10: Coefficient in: baseGold += s.tier * (battle ? 2 + state.depth : 4 + state.depth);
A11: /tuning/treasureRoll.coefficient.1/category | B11: rule.tuning.treasureRoll.coefficient.1 | C11: treasureRoll · coefficient 1 | D11: Loot | E11: string | F11: count or coefficient | I11: READ ONLY
A12: /tuning/treasureRoll.coefficient.1/label | B12: rule.tuning.treasureRoll.coefficient.1 | C12: treasureRoll · coefficient 1 | D12: treasureRoll · coefficient 1 | E12: string | F12: count or coefficient | I12: READ ONLY
A13: /tuning/treasureRoll.coefficient.1/description | B13: rule.tuning.treasureRoll.coefficient.1 | C13: treasureRoll · coefficient 1 | D13: Coefficient in: baseGold += s.tier * (battle ? 2 + state.depth : 4 + state.depth); | E13: string | F13: count or coefficient | I13: READ ONLY
A14: /tuning/treasureRoll.coefficient.1/unit | B14: rule.tuning.treasureRoll.coefficient.1 | C14: treasureRoll · coefficient 1 | D14: count or coefficient | E14: string | F14: count or coefficient | I14: READ ONLY
A15: /tuning/treasureRoll.coefficient.1/min | B15: rule.tuning.treasureRoll.coefficient.1 | C15: treasureRoll · coefficient 1 | D15: 0 | E15: number | F15: count or coefficient | G15: 1 | H15: 100 | I15: READ ONLY
A16: /tuning/treasureRoll.coefficient.1/max | B16: rule.tuning.treasureRoll.coefficient.1 | C16: treasureRoll · coefficient 1 | D16: 100 | E16: number | F16: count or coefficient | G16: 1 | H16: 100 | I16: READ ONLY
A17: /tuning/treasureRoll.coefficient.1/integer | B17: rule.tuning.treasureRoll.coefficient.1 | C17: treasureRoll · coefficient 1 | D17: TRUE | E17: boolean | F17: count or coefficient | I17: READ ONLY
A18: /tuning/treasureRoll.coefficient.2/value | B18: rule.tuning.treasureRoll.coefficient.2 | C18: treasureRoll · coefficient 2 | D18: 4 | E18: number | F18: count or coefficient | G18: 1 | H18: 100 | I18: Coefficient in: s.tier * (battle ? 2 + state.depth : 4 + state.depth); if (s.type === "a
A19: /tuning/treasureRoll.coefficient.2/category | B19: rule.tuning.treasureRoll.coefficient.2 | C19: treasureRoll · coefficient 2 | D19: Loot | E19: string | F19: count or coefficient | I19: READ ONLY
A20: /tuning/treasureRoll.coefficient.2/label | B20: rule.tuning.treasureRoll.coefficient.2 | C20: treasureRoll · coefficient 2 | D20: treasureRoll · coefficient 2 | E20: string | F20: count or coefficient | I20: READ ONLY
A21: /tuning/treasureRoll.coefficient.2/description | B21: rule.tuning.treasureRoll.coefficient.2 | C21: treasureRoll · coefficient 2 | D21: Coefficient in: s.tier * (battle ? 2 + state.depth : 4 + state.depth); if (s.type === "a | E21: string | F21: count or coefficient | I21: READ ONLY
A22: /tuning/treasureRoll.coefficient.2/unit | B22: rule.tuning.treasureRoll.coefficient.2 | C22: treasureRoll · coefficient 2 | D22: count or coefficient | E22: string | F22: count or coefficient | I22: READ ONLY
A23: /tuning/treasureRoll.coefficient.2/min | B23: rule.tuning.treasureRoll.coefficient.2 | C23: treasureRoll · coefficient 2 | D23: 0 | E23: number | F23: count or coefficient | G23: 1 | H23: 100 | I23: READ ONLY
A24: /tuning/treasureRoll.coefficient.2/max | B24: rule.tuning.treasureRoll.coefficient.2 | C24: treasureRoll · coefficient 2 | D24: 100 | E24: number | F24: count or coefficient | G24: 1 | H24: 100 | I24: READ ONLY
A25: /tuning/treasureRoll.coefficient.2/integer | B25: rule.tuning.treasureRoll.coefficient.2 | C25: treasureRoll · coefficient 2 | D25: TRUE | E25: boolean | F25: count or coefficient | I25: READ ONLY
A26: /tuning/treasureRoll.coefficient.3/value | B26: rule.tuning.treasureRoll.coefficient.3 | C26: treasureRoll · coefficient 3 | D26: 2 | E26: number | F26: count or coefficient | G26: 1 | H26: 100 | I26: Coefficient in: if (source === "boss") baseGold *= 2; if (elite) { baseGold *= 3;
A27: /tuning/treasureRoll.coefficient.3/category | B27: rule.tuning.treasureRoll.coefficient.3 | C27: treasureRoll · coefficient 3 | D27: Loot | E27: string | F27: count or coefficient | I27: READ ONLY
A28: /tuning/treasureRoll.coefficient.3/label | B28: rule.tuning.treasureRoll.coefficient.3 | C28: treasureRoll · coefficient 3 | D28: treasureRoll · coefficient 3 | E28: string | F28: count or coefficient | I28: READ ONLY
A29: /tuning/treasureRoll.coefficient.3/description | B29: rule.tuning.treasureRoll.coefficient.3 | C29: treasureRoll · coefficient 3 | D29: Coefficient in: if (source === "boss") baseGold *= 2; if (elite) { baseGold *= 3; | E29: string | F29: count or coefficient | I29: READ ONLY
A30: /tuning/treasureRoll.coefficient.3/unit | B30: rule.tuning.treasureRoll.coefficient.3 | C30: treasureRoll · coefficient 3 | D30: count or coefficient | E30: string | F30: count or coefficient | I30: READ ONLY
A31: /tuning/treasureRoll.coefficient.3/min | B31: rule.tuning.treasureRoll.coefficient.3 | C31: treasureRoll · coefficient 3 | D31: 0 | E31: number | F31: count or coefficient | G31: 1 | H31: 100 | I31: READ ONLY
A32: /tuning/treasureRoll.coefficient.3/max | B32: rule.tuning.treasureRoll.coefficient.3 | C32: treasureRoll · coefficient 3 | D32: 100 | E32: number | F32: count or coefficient | G32: 1 | H32: 100 | I32: READ ONLY
A33: /tuning/treasureRoll.coefficient.3/integer | B33: rule.tuning.treasureRoll.coefficient.3 | C33: treasureRoll · coefficient 3 | D33: TRUE | E33: boolean | F33: count or coefficient | I33: READ ONLY
A34: /tuning/treasureRoll.coefficient.4/value | B34: rule.tuning.treasureRoll.coefficient.4 | C34: treasureRoll · coefficient 4 | D34: 3 | E34: number | F34: count or coefficient | G34: 1 | H34: 100 | I34: Coefficient in: *= 2; if (elite) { baseGold *= 3; const prized = makeArtefact(stat
A35: /tuning/treasureRoll.coefficient.4/category | B35: rule.tuning.treasureRoll.coefficient.4 | C35: treasureRoll · coefficient 4 | D35: Loot | E35: string | F35: count or coefficient | I35: READ ONLY
A36: /tuning/treasureRoll.coefficient.4/label | B36: rule.tuning.treasureRoll.coefficient.4 | C36: treasureRoll · coefficient 4 | D36: treasureRoll · coefficient 4 | E36: string | F36: count or coefficient | I36: READ ONLY
A37: /tuning/treasureRoll.coefficient.4/description | B37: rule.tuning.treasureRoll.coefficient.4 | C37: treasureRoll · coefficient 4 | D37: Coefficient in: *= 2; if (elite) { baseGold *= 3; const prized = makeArtefact(stat | E37: string | F37: count or coefficient | I37: READ ONLY
A38: /tuning/treasureRoll.coefficient.4/unit | B38: rule.tuning.treasureRoll.coefficient.4 | C38: treasureRoll · coefficient 4 | D38: count or coefficient | E38: string | F38: count or coefficient | I38: READ ONLY
A39: /tuning/treasureRoll.coefficient.4/min | B39: rule.tuning.treasureRoll.coefficient.4 | C39: treasureRoll · coefficient 4 | D39: 0 | E39: number | F39: count or coefficient | G39: 1 | H39: 100 | I39: READ ONLY
A40: /tuning/treasureRoll.coefficient.4/max | B40: rule.tuning.treasureRoll.coefficient.4 | C40: treasureRoll · coefficient 4 | D40: 100 | E40: number | F40: count or coefficient | G40: 1 | H40: 100 | I40: READ ONLY
...

Sheet Economy
A1: Stable field ID | B1: Entity ID | C1: Field / label | D1: Value (edit blue cells) | E1: Type | F1: Unit | G1: Minimum | H1: Maximum | I1: Notes
A2: /tuning/shopPrices.coefficient.1/value | B2: rule.tuning.shopPrices.coefficient.1 | C2: shopPrices · coefficient 1 | D2: 14 | E2: number | F2: count or coefficient | G2: 1 | H2: 100 | I2: Coefficient in: .keys(ITEM_DEFS).map((type) => [type, 14 + state.depth * 2]), ), potio
A3: /tuning/shopPrices.coefficient.1/category | B3: rule.tuning.shopPrices.coefficient.1 | C3: shopPrices · coefficient 1 | D3: Economy | E3: string | F3: count or coefficient | I3: READ ONLY
